I'm sorry, but an uncaught exception occurred.

While running game code:
  File "game/script.rpy", line 12, in script
    m "Um... will you..."
Exception: Sayer 'm' is not defined.

-- Full Traceback ------------------------------------------------------------

Full traceback:
  File "game/script.rpy", line 12, in script
    m "Um... will you..."
  File "C:\Users\sqlia\OneDrive\Desktop\renpy-8.2.3-sdk\renpy-8.2.3-sdk\renpy\ast.py", line 2560, in execute
    Say.execute(self)
  File "C:\Users\sqlia\OneDrive\Desktop\renpy-8.2.3-sdk\renpy-8.2.3-sdk\renpy\ast.py", line 575, in execute
    who = eval_who(self.who, self.who_fast)
  File "C:\Users\sqlia\OneDrive\Desktop\renpy-8.2.3-sdk\renpy-8.2.3-sdk\renpy\ast.py", line 464, in eval_who
    raise Exception("Sayer '%s' is not defined." % who)
Exception: Sayer 'm' is not defined.

Windows-10-10.0.22631 AMD64
Ren'Py 8.2.3.24061702
Hospice 1.0
Thu Aug 29 18:56:56 2024
